2023-12-23 06:34:48 | ERROR    | __main__:run:158 | An error has been caught in function 'run', process 'MainProcess' (3512), thread 'MainThread' (139805046111104): - {}
Traceback (most recent call last):
  File "/home/runner/work/epic-unreal-claimer/epic-unreal-claimer/epic/src/claim.py", line 162, in <module>
    asyncio.run(run())
  File "/opt/hostedtoolcache/Python/3.10.13/x64/lib/python3.10/asyncio/runners.py", line 44, in run
    return loop.run_until_complete(main)
  File "/opt/hostedtoolcache/Python/3.10.13/x64/lib/python3.10/asyncio/base_events.py", line 636, in run_until_complete
    self.run_forever()
  File "/opt/hostedtoolcache/Python/3.10.13/x64/lib/python3.10/asyncio/base_events.py", line 603, in run_forever
    self._run_once()
  File "/opt/hostedtoolcache/Python/3.10.13/x64/lib/python3.10/asyncio/base_events.py", line 1909, in _run_once
    handle._run()
  File "/opt/hostedtoolcache/Python/3.10.13/x64/lib/python3.10/asyncio/events.py", line 80, in _run
    self._context.run(self._callback, *self._args)
> File "/home/runner/work/epic-unreal-claimer/epic-unreal-claimer/epic/src/claim.py", line 158, in run
    await agent.stash()
  File "/home/runner/work/epic-unreal-claimer/epic-unreal-claimer/epic/src/claim.py", line 151, in stash
    await self.claim_epic_games(context)
  File "/home/runner/work/epic-unreal-claimer/epic-unreal-claimer/epic/src/claim.py", line 98, in claim_epic_games
    if await epic.authorize(page):
  File "/home/runner/work/epic-unreal-claimer/epic-unreal-claimer/epic/src/epic_games/agent.py", line 260, in authorize
    match await self._login(page):
  File "/home/runner/work/epic-unreal-claimer/epic-unreal-claimer/epic/src/epic_games/agent.py", line 244, in _login
    await insert_challenge(stage="email_exists_prod")
  File "/home/runner/work/epic-unreal-claimer/epic-unreal-claimer/epic/src/epic_games/agent.py", line 217, in insert_challenge
    result = await self._solver.execute(window=stage)
  File "/opt/hostedtoolcache/Python/3.10.13/x64/lib/python3.10/site-packages/hcaptcha_challenger/agents/playwright/control.py", line 642, in execute
    await self._catch_all_binary_challenge(frame_challenge)
  File "/opt/hostedtoolcache/Python/3.10.13/x64/lib/python3.10/site-packages/hcaptcha_challenger/agents/playwright/control.py", line 498, in _catch_all_binary_challenge
    results = tool(model, image=Image.open(self.img_paths[i + pth * 9]))
  File "/opt/hostedtoolcache/Python/3.10.13/x64/lib/python3.10/site-packages/PIL/Image.py", line 3305, in open
    raise UnidentifiedImageError(msg)
PIL.UnidentifiedImageError: cannot identify image file '/opt/hostedtoolcache/Python/3.10.13/x64/lib/python3.10/site-packages/hcaptcha_challenger/agents/tmp_dir/image_label_binary/liquid water/d41d8cd98f00b204e9800998ecf8427e.png'
